Workbook
Name Дисциплина: #REF!
Name Дисциплина: #REF!
Name Опыт: #REF!
Name Опыт: #REF!
Name ПДЗ: #REF!
Name ПДЗ: #REF!
Name ПДЗ: #REF!

Sheet РСБУ расчет лимита
F1: ЭКСПРЕСС-ОЦЕНКА КОНТРАГЕНТА
K3: Дата оценки | L3: 46266 | N3: (Голубая ячейка заполняется вручную)
B5: ДАННЫЕ О КОНТРАГЕНТЕ
B7: 1.1 Наименование контрагента: | H7: ООО "КОМПАНИЯ" | N7: (Голубая ячейка заполняется вручную)
B8: 1.2 ИНН контрагента: | H8: 1234567890 | N8: (Голубая ячейка заполняется вручную)
B9: 1.3 Код контрагента в системе учета (при наличии): | N9: (Заполняется вручную)
B10: 1.3 Код основного вида деятельности (ОКВЭД) | H10: 20.41.2 | J10: Категория | K10: =IFERROR(IF(OR(AND(MID($H$10,1,2)*1<=43, MID($H$10,1,2)*1>=41),MID($H$10,1,2)*1=71),"Строительство",IF(OR(MID($H$10,1,2)*1=6,MID($H$10,1,4)="49.5",MID($H$10,1,2)*1=9,MID($H$10,1,4)="19.2"),"Добыча, переработка и транспортировка газа, нефти и нефтепродуктов",IF(OR(MID($H$10,1,2)*1=49,MID($H$10,1,2)*1=53,MID($H$10,1,2)*1=52),"Транспортировка и хранение",IF(OR(AND(MID($H$10,1,2)*1<=47, MID($H$10,1,2)*1>=45)),"Торговля",IF(OR(AND(MID($H$10,1,2)*1<=33, MID($H$10,1,2)*1>=10),MID($H$10,1,2)*1=35,MID($H$10,1,2)*1=5,MID($H$10,1,2)*1=7,MID($H$10,1,2)*1=8),"Производство",IF(OR(MID($H$10,1,2)*1=51),"Авиакомпания",IF(OR(MID($H$10,1,2)*1=50),"Судовладелец",IF(OR(MID($H$10,1,2)*1=62,MID($H$10,1,2)*1=63),"ИТ","Прочие")))))))),"Укажите код ОКВЭД") -> Производство | N10: (Голубая ячейка заполняется вручную)
B11: 1.4 Наличие СТОП-факторов: | H11: Нет | N11: (В голубой ячейке выбрать значение из списка)
B13: ИТОГОВОЕ ЗАКЛЮЧЕНИЕ
H14: =J22 -> 46022 | L14: =L22 -> 45657 | N14: (Автоматический расчет)
B15: ВНУТРЕННИЙ КРЕДИТНЫЙ РЕЙТИНГ | H15: =J61&J60 -> B1 | J15: =J60 -> 1 | M15: =L61&L60 -> B1 | N15: (Автоматический расчет)
B16: СКОРИНГ-БАЛЛ | H16: =ROUND(J58,0)&" "&K58 -> 84 из 100 | J16: =J58 -> 84 | M16: =L58&" "&K58 -> 80 из 100 | N16: (Автоматический расчет)
B17: ="КРЕДИТНЫЙ ЛИМИТ КОНТРАГЕНТА, "&'РСБУ отчетность'!C2&'РСБУ отчетность'!C3 -> КРЕДИТНЫЙ ЛИМИТ КОНТРАГЕНТА, тыс. руб. | H17: =J92 -> 1912919.9 | J17: =H17 -> 1912919.9 | K17: =L86*L88*L90*(1-L91) -> 1580215.5 | L17: =L92 -> 1580215.5 | N17: (Автоматический расчет)
B18: ="ЛИМИТ АВАНСОВОГО ПЛАТЕЖА, "&'РСБУ отчетность'!C2&'РСБУ отчетность'!C3 -> ЛИМИТ АВАНСОВОГО ПЛАТЕЖА, тыс. руб. | H18: =J93 -> 58919.895 | J18: =H18 -> 58919.895 | L18: =L93 -> 40481.007 | N18: (Автоматический расчет)
B20: 1. ФИНАНСОВЫЕ ПОКАЗАТЕЛИ
J22: ='РСБУ отчетность'!E5 -> 46022 | L22: ='РСБУ отчетность'!F5 -> 45657 | N22: (Автоматический расчет)
B23: Наименование показателя | I23: Макс. балл | J23: Значение | K23: Баллы | L23: Значение | M23: Баллы
B24: 1.1 Коэффициент текущей ликвидности | I24: 10 | J24: ='РСБУ отчетность'!E79 -> 3.2836953 | K24: =ROUND(IF(J24="",0,IF($K$10="Строительство",Подложка!G45*I24/100,IF($K$10="Добыча, переработка и транспортировка газа, нефти и нефтепродуктов",Подложка!L45*I24/100,IF($K$10="Транспортировка и хранение",Подложка!Q45*I24/100,IF($K$10="Торговля",Подложка!V45*I24/100,IF($K$10="Производство",Подложка!AA45*I24/100,IF($K$10="Авиакомпания",Подложка!AF45*I24/100,IF($K$10="Судовладелец",Подложка!AK45*I24/100,IF($K$10="Прочие",Подложка!AP45*I24/100,IF($K$10="ИТ",Подложка!AU45*I24/100,0)))))))))),0) -> 10 | L24: ='РСБУ отчетность'!F79 -> 2.9821276 | M24: =IF(L24="",0,IF($K$10="Строительство",Подложка!G55*I24/100,IF($K$10="Добыча, переработка и транспортировка газа, нефти и нефтепродуктов",Подложка!L55*I24/100,IF($K$10="Транспортировка и хранение",Подложка!Q55*I24/100,IF($K$10="Торговля",Подложка!V55*I24/100,IF($K$10="Производство",Подложка!AA55*I24/100,IF($K$10="Авиакомпания",Подложка!AF55*I24/100,IF($K$10="Судовладелец",Подложка!AK55*I24/100,IF($K$10="Прочие",Подложка!AP55*I24/100,IF($K$10="ИТ",Подложка!AU55*I24/100,0)))))))))) -> 10 | N24: (Автоматический расчет)
B25: 1.2 Коэффициент быстрой ликвидности | I25: 5 | J25: ='РСБУ отчетность'!E80 -> 1.7494151 | K25: =ROUND(IF(J25="",0,IF($K$10="Строительство",Подложка!G46*I25/100,IF($K$10="Добыча, переработка и транспортировка газа, нефти и нефтепродуктов",Подложка!L46*I25/100,IF($K$10="Транспортировка и хранение",Подложка!Q46*I25/100,IF($K$10="Торговля",Подложка!V46*I25/100,IF($K$10="Производство",Подложка!AA46*I25/100,IF($K$10="Авиакомпания",Подложка!AF46*I25/100,IF($K$10="Судовладелец",Подложка!AK46*I25/100,IF($K$10="Прочие",Подложка!AP46*I25/100,IF($K$10="ИТ",Подложка!AU46*I25/100,0)))))))))),0) -> 5 | L25: ='РСБУ отчетность'!F80 -> 1.755559 | M25: =IF(L25="",0,IF($K$10="Строительство",Подложка!G56*I25/100,IF($K$10="Добыча, переработка и транспортировка газа, нефти и нефтепродуктов",Подложка!L56*I25/100,IF($K$10="Транспортировка и хранение",Подложка!Q56*I25/100,IF($K$10="Торговля",Подложка!V56*I25/100,IF($K$10="Производство",Подложка!AA56*I25/100,IF($K$10="Авиакомпания",Подложка!AF56*I25/100,IF($K$10="Судовладелец",Подложка!AK56*I25/100,IF($K$10="Прочие",Подложка!AP56*I25/100,IF($K$10="ИТ",Подложка!AU56*I25/100,0)))))))))) -> 5 | N25: (Автоматический расчет)
B26: 1.3 Длительность операционного цикла | I26: 5 | J26: ='РСБУ отчетность'!E81 -> 166.83719 | K26: =ROUND(IF($K$10="Строительство",Подложка!G47*I26/100,IF($K$10="Добыча, переработка и транспортировка газа, нефти и нефтепродуктов",Подложка!L47*I26/100,IF($K$10="Транспортировка и хранение",Подложка!Q47*I26/100,IF($K$10="Торговля",Подложка!V47*I26/100,IF($K$10="Производство",Подложка!AA47*I26/100,IF($K$10="Авиакомпания",Подложка!AF47*I26/100,IF($K$10="Судовладелец",Подложка!AK47*I26/100,IF($K$10="Прочие",Подложка!AP47*I26/100,IF($K$10="ИТ",Подложка!AU47*I26/100,0))))))))),0) -> 0 | L26: ='РСБУ отчетность'!F81 -> 140.56013 | M26: =IF(L26="",0,IF($K$10="Строительство",Подложка!G57*I26/100,IF($K$10="Добыча, переработка и транспортировка газа, нефти и нефтепродуктов",Подложка!L57*I26/100,IF($K$10="Транспортировка и хранение",Подложка!Q57*I26/100,IF($K$10="Торговля",Подложка!V57*I26/100,IF($K$10="Производство",Подложка!AA57*I26/100,IF($K$10="Авиакомпания",Подложка!AF57*I26/100,IF($K$10="Судовладелец",Подложка!AK57*I26/100,IF($K$10="Прочие",Подложка!AP57*I26/100,IF($K$10="ИТ",Подложка!AU57*I26/100,0)))))))))) -> 0 | N26: (Автоматический расчет)
B27: 1.4 Коэффициент автономии | I27: 10 | J27: ='РСБУ отчетность'!E82 -> 0.70509515 | K27: =ROUND(IF(J27="",0,IF($K$10="Строительство",Подложка!G48*I27/100,IF($K$10="Добыча, переработка и транспортировка газа, нефти и нефтепродуктов",Подложка!L48*I27/100,IF($K$10="Транспортировка и хранение",Подложка!Q48*I27/100,IF($K$10="Торговля",Подложка!V48*I27/100,IF($K$10="Производство",Подложка!AA48*I27/100,IF($K$10="Авиакомпания",Подложка!AF48*I27/100,IF($K$10="Судовладелец",Подложка!AK48*I27/100,IF($K$10="Прочие",Подложка!AP48*I27/100,IF($K$10="ИТ",Подложка!AU48*I27/100,0)))))))))),0) -> 10 | L27: ='РСБУ отчетность'!F82 -> 0.67351065 | M27: =IF(L27="",0,IF($K$10="Строительство",Подложка!G58*I27/100,IF($K$10="Добыча, переработка и транспортировка газа, нефти и нефтепродуктов",Подложка!L58*I27/100,IF($K$10="Транспортировка и хранение",Подложка!Q58*I27/100,IF($K$10="Торговля",Подложка!V58*I27/100,IF($K$10="Производство",Подложка!AA58*I27/100,IF($K$10="Авиакомпания",Подложка!AF58*I27/100,IF($K$10="Судовладелец",Подложка!AK58*I27/100,IF($K$10="Прочие",Подложка!AP58*I27/100,IF($K$10="ИТ",Подложка!AU58*I27/100,0)))))))))) -> 7 | N27: (Автоматический расчет)
B28: 1.5 Рентабельность продаж | I28: 5 | J28: ='РСБУ отчетность'!E83 -> 9.6934592 | K28: =ROUND(IF(J28="",0,IF($K$10="Строительство",Подложка!G49*I28/100,IF($K$10="Добыча, переработка и транспортировка газа, нефти и нефтепродуктов",Подложка!L49*I28/100,IF($K$10="Транспортировка и хранение",Подложка!Q49*I28/100,IF($K$10="Торговля",Подложка!V49*I28/100,IF($K$10="Производство",Подложка!AA49*I28/100,IF($K$10="Авиакомпания",Подложка!AF49*I28/100,IF($K$10="Судовладелец",Подложка!AK49*I28/100,IF($K$10="Прочие",Подложка!AP49*I28/100,IF($K$10="ИТ",Подложка!AU49*I28/100,0)))))))))),0) -> 4 | L28: ='РСБУ отчетность'!F83 -> 21.337774 | M28: =IF(L28="",0,IF($K$10="Строительство",Подложка!G59*I28/100,IF($K$10="Добыча, переработка и транспортировка газа, нефти и нефтепродуктов",Подложка!L59*I28/100,IF($K$10="Транспортировка и хранение",Подложка!Q59*I28/100,IF($K$10="Торговля",Подложка!V59*I28/100,IF($K$10="Производство",Подложка!AA59*I28/100,IF($K$10="Авиакомпания",Подложка!AF59*I28/100,IF($K$10="Судовладелец",Подложка!AK59*I28/100,IF($K$10="Прочие",Подложка!AP59*I28/100,IF($K$10="ИТ",Подложка!AU59*I28/100,0)))))))))) -> 5 | N28: (Автоматический расчет)
B29: 1.6 Коэффициент долговой нагрузки | I29: 10 | J29: ='РСБУ отчетность'!E84 -> 0.30470929 | K29: =ROUND(IF(J29=0,I29,IF(OR(J29="",J29<0),0,IF($K$10="Строительство",Подложка!G50*I29/100,IF($K$10="Добыча, переработка и транспортировка газа, нефти и нефтепродуктов",Подложка!L50*I29/100,IF($K$10="Транспортировка и хранение",Подложка!Q50*I29/100,IF($K$10="Торговля",Подложка!V50*I29/100,IF($K$10="Производство",Подложка!AA50*I29/100,IF($K$10="Авиакомпания",Подложка!AF50*I29/100,IF($K$10="Судовладелец",Подложка!AK50*I29/100,IF($K$10="Прочие",Подложка!AP50*I29/100,IF($K$10="ИТ",Подложка!AU50*I29/100,0))))))))))),0) -> 7 | L29: ='РСБУ отчетность'!F84 -> 0.16220914 | M29: =IF(L29="",0,IF($K$10="Строительство",Подложка!G60*I29/100,IF($K$10="Добыча, переработка и транспортировка газа, нефти и нефтепродуктов",Подложка!L60*I29/100,IF($K$10="Транспортировка и хранение",Подложка!Q60*I29/100,IF($K$10="Торговля",Подложка!V60*I29/100,IF($K$10="Производство",Подложка!AA60*I29/100,IF($K$10="Авиакомпания",Подложка!AF60*I29/100,IF($K$10="Судовладелец",Подложка!AK60*I29/100,IF($K$10="Прочие",Подложка!AP60*I29/100,IF($K$10="ИТ",Подложка!AU60*I29/100,0)))))))))) -> 7 | N29: (Автоматический расчет)
B30: 1.7 Коэффициент покрытия процентов | I30: 5 | J30: ='РСБУ отчетность'!E85 -> 18.721681 | K30: =ROUND(IF(J30=0,I30,IF(OR(J30="",J30<0),0,IF($K$10="Строительство",Подложка!G51*I30/100,IF($K$10="Добыча, переработка и транспортировка газа, нефти и нефтепродуктов",Подложка!L51*I30/100,IF($K$10="Транспортировка и хранение",Подложка!Q51*I30/100,IF($K$10="Торговля",Подложка!V51*I30/100,IF($K$10="Производство",Подложка!AA51*I30/100,IF($K$10="Авиакомпания",Подложка!AF51*I30/100,IF($K$10="Судовладелец",Подложка!AK51*I30/100,IF($K$10="Прочие",Подложка!AP51*I30/100,IF($K$10="ИТ",Подложка!AU51*I30/100,0))))))))))),0) -> 5 | L30: ='РСБУ отчетность'!F85 -> 34.086001 | M30: =IF(L30="",0,IF($K$10="Строительство",Подложка!G61*I30/100,IF($K$10="Добыча, переработка и транспортировка газа, нефти и нефтепродуктов",Подложка!L61*I30/100,IF($K$10="Транспортировка и хранение",Подложка!Q61*I30/100,IF($K$10="Торговля",Подложка!V61*I30/100,IF($K$10="Производство",Подложка!AA61*I30/100,IF($K$10="Авиакомпания",Подложка!AF61*I30/100,IF($K$10="Судовладелец",Подложка!AK61*I30/100,IF($K$10="Прочие",Подложка!AP61*I30/100,IF($K$10="ИТ",Подложка!AU61*I30/100,0)))))))))) -> 5 | N30: (Автоматический расчет)
B31: 1.8 Коэффициент маневренности | I31: 5 | J31: ='РСБУ отчетность'!E86 -> 0.68527449 | K31: =ROUND(IF(J24="",0,IF(OR(J31="",J31<0),0,IF($K$10="Строительство",Подложка!G52*I31/100,IF($K$10="Добыча, переработка и транспортировка газа, нефти и нефтепродуктов",Подложка!L52*I31/100,IF($K$10="Транспортировка и хранение",Подложка!Q52*I31/100,IF($K$10="Торговля",Подложка!V52*I31/100,IF($K$10="Производство",Подложка!AA52*I31/100,IF($K$10="Авиакомпания",Подложка!AF52*I31/100,IF($K$10="Судовладелец",Подложка!AK52*I31/100,IF($K$10="Прочие",Подложка!AP52*I31/100,IF($K$10="ИТ",Подложка!AU52*I31/100,0))))))))))),0) -> 5 | L31: ='РСБУ отчетность'!F86 -> 0.65401698 | M31: =IF(L31="",0,IF($K$10="Строительство",Подложка!G62*I31/100,IF($K$10="Добыча, переработка и транспортировка газа, нефти и нефтепродуктов",Подложка!L62*I31/100,IF($K$10="Транспортировка и хранение",Подложка!Q62*I31/100,IF($K$10="Торговля",Подложка!V62*I31/100,IF($K$10="Производство",Подложка!AA62*I31/100,IF($K$10="Авиакомпания",Подложка!AF62*I31/100,IF($K$10="Судовладелец",Подложка!AK62*I31/100,IF($K$10="Прочие",Подложка!AP62*I31/100,IF($K$10="ИТ",Подложка!AU62*I31/100,0)))))))))) -> 5 | N31: (Автоматический расчет)
B32: 1.9 Рентабельность капитала | I32: 4 | J32: ='РСБУ отчетность'!E87 -> 26.007659 | K32: =ROUND(IF(J32="",0,IF(OR(J32="",J32<0),0,IF($K$10="Строительство",Подложка!G53*I32/100,IF($K$10="Добыча, переработка и транспортировка газа, нефти и нефтепродуктов",Подложка!L53*I32/100,IF($K$10="Транспортировка и хранение",Подложка!Q53*I32/100,IF($K$10="Торговля",Подложка!V53*I32/100,IF($K$10="Производство",Подложка!AA53*I32/100,IF($K$10="Авиакомпания",Подложка!AF53*I32/100,IF($K$10="Судовладелец",Подложка!AK53*I32/100,IF($K$10="Прочие",Подложка!AP53*I32/100,IF($K$10="ИТ",Подложка!AU53*I32/100,0))))))))))),0) -> 3 | L32: ='РСБУ отчетность'!F87 -> 65.990771 | M32: =IF(L32="",0,IF($K$10="Строительство",Подложка!G63*I32/100,IF($K$10="Добыча, переработка и транспортировка газа, нефти и нефтепродуктов",Подложка!L63*I32/100,IF($K$10="Транспортировка и хранение",Подложка!Q63*I32/100,IF($K$10="Торговля",Подложка!V63*I32/100,IF($K$10="Производство",Подложка!AA63*I32/100,IF($K$10="Авиакомпания",Подложка!AF63*I32/100,IF($K$10="Судовладелец",Подложка!AK63*I32/100,IF($K$10="Прочие",Подложка!AP63*I32/100,IF($K$10="ИТ",Подложка!AU63*I32/100,0)))))))))) -> 4 | N32: (Автоматический расчет)
B33: 1.10 Динамика ликвидности | I33: 3 | J33: ='РСБУ отчетность'!E88 -> Рост | K33: =VLOOKUP(J33,Подложка!$AD$3:$AE$6,2,0) -> 3 | L33: ='РСБУ отчетность'!F88 -> На прежнем уровне | M33: =VLOOKUP(L33,Подложка!$AD$3:$AE$6,2,0) -> 0 | N33: (Автоматический расчет)
B34: 1.11 Динамика рентабельности продаж | I34: 3 | J34: ='РСБУ отчетность'!E89 -> Снижение | K34: =VLOOKUP(J34,Подложка!$AD$3:$AE$6,2,0) -> -3 | L34: ='РСБУ отчетность'!F89 -> Снижение | M34: =VLOOKUP(L34,Подложка!$AD$3:$AE$6,2,0) -> -3 | N34: (Автоматический расчет)
B35: Итого баллов с учетом веса показателей | I35: =SUM(I24:I34) -> 65 | K35: =SUM(K24:K34) -> 49 | M35: =SUM(M24:M34) -> 45 | N35: (Автоматический расчет)
B37: 2. ПОКАЗАТЕЛИ ДЕЛОВОЙ РЕПУТАЦИИ
J39: ='РСБУ отчетность'!E5 -> 46022 | L39: ='РСБУ отчетность'!F5 -> 45657 | N39: (Автоматический расчет)
B40: Наименование показателя | I40: Макс. балл | J40: Значение | K40: Баллы | L40: Значение | M40: Баллы
B41: 2.1 Опыт работы с контрагентом | I41: 5 | J41: более 3-х лет | K41: =IF($J$41="более 3-х лет",100*I41/100,IF($J$41="от 1 до 3-х лет",70*I41/100,IF($J$41="менее 1 года",40*I41/100,0))) -> 5 | L41: более 3-х лет | M41: =IF($L$41="более 3-х лет",100*I41/100,IF($L$41="от 1 до 3-х лет",70*I41/100,IF($L$41="менее 1 года",40*I41/100,0))) -> 5 | N41: (В голубых ячейках выбрать значение из списка)
B42: 2.2 Платежная дисциплина контрагента | I42: 15 | J42: ПДЗ отсутствовала | K42: =IF(OR(J42="ПДЗ отсутствовала",J42="Техническая ПДЗ"),15,IF(J42="Разовая ПДЗ продолжительностью менее 30 дней",10,IF(J42="Разовая ПДЗ продолжительностью более 30 дней",7.5,IF(J42="Неоднократное возникновение ПДЗ",3.5,IF(J42="Информация отсутствует",3.5,0))))) -> 15 | L42: ПДЗ отсутствовала | M42: =IF(OR(L42="ПДЗ отсутствовала",L42="Техническая ПДЗ"),15,IF(L42="Разовая ПДЗ продолжительностью менее 30 дней",10,IF(L42="Разовая ПДЗ продолжительностью более 30 дней",7.5,IF(L42="Неоднократное возникновение ПДЗ",3.5,IF(L42="Информация отсутствует",3.5,0))))) -> 15 | N42: (В голубых ячейках выбрать значение из списка)
B43: Итого баллов с учетом веса показателей | I43: 20 | K43: =SUM(K41:K42) -> 20 | M43: =SUM(M41:M42) -> 20 | N43: (Автоматический расчет)
B45: 3. ПОКАЗАТЕЛИ ИЗ ВНЕШНИХ ИСТОЧНИКОВ
J48: ='РСБУ отчетность'!E5 -> 46022
B49: Повышающие показатели | I49: Макс. балл | J49: Значение | K49: Баллы | L49: Дата регистрации
B50: 3.1 Возраст компании | I50: 5 | J50: =IF(OR(L50="",L50=0),"Информация отсутствует",IF(L50>TODAY(),"Информация некорректна",IF(TODAY()-L50<730,"Менее 2 лет",IF(TODAY()-L50<1825,"От 2 до 5-и лет","Более 5 лет")))) -> Более 5 лет | K50: =IF(OR(L50="Информация отсутствует",L50="Информация некорректна"),0,IF(L50="Менее 2 лет",40*I50/100,IF(L50="От 2 до 5-и лет",70*I50/100,100*I50/100))) -> 5 | L50: 34928 | N50: (Голубая ячейка заполняется вручную)
B51: 3.2 Сводный индикатор риска СПАРК | I51: 10 | J51: Низкий | K51: =IF(J51="Информация отсутствует",0.001,IF(J51="Низкий",100*I51/100,IF(J51="Средний",50*I51/100,0))) -> 10 | N51: (В голубой ячейке выбрать значение из списка)
...

Sheet РСБУ отчетность
A1: ДАННЫЕ ОТЧЕТНОСТИ | F1: заполнять вручную
A2: Единица измерения | C2: тыс. | F2: заполняется автоматически
A3: Валюта отчетности | C3: руб.
A4: Бухгалтерский баланс (Форма №1)
D5: Код строки | E5: 46022 | F5: 45657 | G5: 45291
A6: АКТИВ
A7: I. Внеоборотные активы: | D7: 1100 | E7: =SUM(E8:E18) -> 199517 | F7: =SUM(F8:F18) -> 158892 | G7: =SUM(G8:G18) -> 136886
A8: Нематериальные активы | D8: 1110 | E8: =18170 -> 18170 | F8: 33163 | G8: 39653
A9: Результаты исследований и разработок | D9: 1120 | E9: 0 | F9: 0 | G9: 0
A10: Нематериальные поисковые активы | D10: 1130 | E10: 0 | F10: 0 | G10: 0
A11: Материальные поисковые активы | D11: 1140 | E11: 0 | F11: 0 | G11: 0
A12: Основные средства (в т.ч. НЗ) | D12: 1150 | E12: 173805 | F12: 119413 | G12: 94029
A13: Право пользования активом | D13: 1157 | E13: 0 | F13: 0 | G13: 0
A14: Инвестиционная недвижимость | D14: 1160 | E14: 0 | F14: 0 | G14: 0
A15: Финансовые вложения | D15: 1170 | E15: 900 | F15: 812 | G15: 822
A16: Отложенные налоговые активы | D16: 1180 | E16: 6642 | F16: 5504 | G16: 2382
A17: Дебиторская задолженность, платежи по которой ожидаются более чем через 12 месяцев после отчетной даты | D17: 1185
A18: Прочие внеоборотные активы | D18: 1190 | E18: 0 | F18: 0 | G18: 0
A19: II. Оборотные активы | D19: 1200 | E19: =SUM(E20:E23,E25:E27) -> 2935952 | F19: =SUM(F20:F23,F25:F27) -> 2661200 | G19: =SUM(G20:G23,G25:G27) -> 1806482
A20: Запасы | D20: 1210 | E20: 1351289 | F20: 1061615 | G20: 932045
A21: Долгосрочные активы к продаже | D21: 1215 | E21: 0 | F21: 0 | G21: 0
A22: НДС по приобретенным ценностям | D22: 1220 | E22: 7 | F22: 0 | G22: 0
A23: Дебиторская задолженность | D23: 1230 | E23: 1354059 | F23: 1470512 | G23: 732868
A24: Задолженность учредителей по взносам в УК | D24: 1237 | E24: 0 | F24: 0 | G24: 0
A25: Фин.вложения (за искл.денеж.эквивалентов) | D25: 1240 | E25: 0 | F25: 15000 | G25: 75905
A26: Денежные средства и денежные эквиваленты | D26: 1250 | E26: 210093 | F26: 96119 | G26: 44876
A27: Прочие оборотные активы | D27: 1260 | E27: 20504 | F27: 17954 | G27: 20788
A28: ИТОГО АКТИВ | D28: 1600 | E28: =E7+E19 -> 3135469 | F28: =F7+F19 -> 2820092 | G28: =G7+G19 -> 1943368
A29: ПАССИВ
A30: III. Капитал и резервы: | D30: 1300 | E30: =SUM(E31:E36) -> 2210804 | F30: =SUM(F31:F36) -> 1899362 | G30: =SUM(G31:G36) -> 1345353
A31: Уставной капитал | D31: 1310 | E31: 19896 | F31: 19896 | G31: 19896
A32: Собственные акции, выкупленные у акционеров | D32: 1320 | E32: 0 | F32: 0
A33: Накопленная дооценка внеоборотных активов | D33: 1340 | E33: 20729 | F33: 86449 | G33: 86449
A34: Добавочный капитал (без накопленной дооценки) | D34: 1350 | E34: 33333 | F34: 33333 | G34: 33333
A35: Резервный капитал | D35: 1360 | E35: 995 | F35: 995 | G35: 995
A36: Нераспределенная прибыль (непокрытый убыток) | D36: 1370 | E36: 2135851 | F36: 1758689 | G36: 1204680
A37: IV. Долгосрочные обязательства | D37: 1400 | E37: =SUM(E38:E42) -> 4010 | F37: =SUM(F38:F42) -> 7556 | G37: =SUM(G38:G42) -> 7277
A38: Заемные средства | D38: 1410 | F38: 0 | G38: 0
A39: Отложенные налоговые обязательства | D39: 1420 | E39: 4010 | F39: 7556 | G39: 7277
A40: Оценочные обязательства | D40: 1430 | E40: 0 | F40: 0 | G40: 0
...

Sheet Подложка
A2: Коды ОКВЭД | C2: Сводный индикатор риска СПАРК | E2: Реестр недобросовестных поставщиков | G2: Класс | I2: Наличие СТОП-факторов | K2: Опыт работы с контрагентом | M2: Наличие просроченной дебиторской задолженности с ГК ГПН | O2: Категория контрагента | Q2: Наличие досудебных претензий | R2: Штраф | S2: Наличие исковых требований | T2: Штраф | X2: ВКР (Графовый индикатор) | Y2: Баллы (Графовый индикатор) | Z2: Баллы (Исковый индикатор) | AD2: Для коэф | AG2: для налогов
A3: 41-43, 71 | C3: Низкий | E3: Отсутствует в реестре | G3: A | I3: Нет | K3: более 3-х лет | M3: ПДЗ отсутствовала | O3: Строительство | Q3: Отсутствуют | R3: 0 | S3: Наличие судебных разбирательств с ГК ГПН | T3: 50 | X3: AAA | Y3: 10 | Z3: 10 | AD3: Рост | AE3: 3 | AG3: более 10%
A4: 62-63 | C4: Средний | E4: Включен в реестр | G4: B | I4: Да, контрагент ликвидирован | K4: от 1 до 3-х лет | M4: Техническая ПДЗ | O4: Добыча, переработка и транспортировка газа, нефти и нефтепродуктов | Q4: 1 претензия | R4: 5 | S4: Приняты решения суда в пользу ГК ГПН | T4: 70 | X4: AA+ | Y4: 8 | Z4: 8 | AD4: Снижение | AE4: -3 | AG4: не более 10%
A5: 06, 49.5, 09, 19.2 | C5: Высокий | E5: Информация отсутствует | G5: C | I5: Да, контрагент находится в состоянии банкротства | K5: менее 1 года | M5: Разовая ПДЗ продолжительностью менее 30 дней | O5: Транспортировка и хранение | Q5: 2-3 претензии | R5: 15 | S5: Отсутствуют | T5: 0 | X5: AA | Y5: 8 | Z5: 8 | AD5: На прежнем уровне | AE5: 0 | AG5: Информация отсутствует
A6: 49-53, за искл. 49.5, 51, 50 | C6: Информация отсутствует | I6: Да, отрицательные Чистые активы за последние 2 года | K6: отсутствует | M6: Разовая ПДЗ продолжительностью более 30 дней | O6: Торговля | Q6: 4-6 претензии | R6: 30 | X6: AA- | Y6: 8 | Z6: 8 | AD6: Нет данных | AE6: 0
A7: 45-47 | M7: Неоднократное возникновение ПДЗ | O7: Производство | Q7: 7 и более претензий | R7: 50 | X7: A+ | Y7: 5 | Z7: 5
A8: 10-33, 35, за искл.19.2 | M8: Наличие проблем по взысканию задолженности с контрагента (судебные разбирательства, исполнительное производство) | O8: Авиакомпания | X8: A | Y8: 5 | Z8: 5
A9: 51 | M9: Информация отсутствует | O9: Судовладелец | X9: A- | Y9: 5 | Z9: 5
A10: 50 | O10: Прочие | X10: BBB+ | Y10: 3 | Z10: 3
O11: ИТ | X11: BBB | Y11: 3 | Z11: 3
X12: BBB- | Y12: 3 | Z12: 3
X13: BB+ | Y13: 0 | Z13: 0
X14: BB | Y14: 0 | Z14: 0
A15: РСБУ | E15: МСФО | X15: BB- | Y15: 0 | Z15: 0
A16: Текущий период точка | E16: Текущий период точка | X16: B+ | Y16: -3 | Z16: -6
A17: ось X | B17: ось Y | E17: ось X | F17: ось Y | X17: B | Y17: -3 | Z17: -6
A18: 1 | B18: =IF(A18=$A$28,$A$29,"") -> 2 | E18: 1 | F18: =IF(E18=$E$28,$E$29,"") -> 1 | X18: B- | Y18: -3 | Z18: -6
A19: 2 | B19: =IF(A19=$A$28,$A$29,"") | E19: 2 | F19: =IF(E19=$E$28,$E$29,"") | X19: CCC+ | Y19: -5 | Z19: -12
A20: 3 | B20: =IF(A20=$A$28,$A$29,"") | E20: 3 | F20: =IF(E20=$E$28,$E$29,"") | X20: CCC | Y20: -5 | Z20: -12
A21: 4 | B21: =IF(A21=$A$28,$A$29,"") | E21: 4 | F21: =IF(E21=$E$28,$E$29,"") | X21: CCC- | Y21: -5 | Z21: -12
X22: CC+ | Y22: -8 | Z22: -18
A23: Мэппинг | E23: Мэппинг | X23: CC | Y23: -8 | Z23: -18
A24: A | B24: 3 | E24: A | F24: 3 | X24: CC- | Y24: -8 | Z24: -18
A25: B | B25: 2 | E25: B | F25: 2 | X25: C | Y25: -10 | Z25: -25
A26: C | B26: 1 | E26: C | F26: 1 | X26: C- | Y26: -10 | Z26: -25
X27: NR | Y27: 0 | Z27: 0
A28: ='РСБУ расчет лимита'!J60 -> 1 | E28: ='МСФО расчет лимита'!$J$57 -> 1 | X28: Нет данных | Y28: 0 | Z28: 0
A29: =INDEX(B24:B26,MATCH('РСБУ расчет лимита'!J61,Подложка!A24:A26,0)) -> 2 | E29: =INDEX(F24:F26,MATCH('МСФО расчет лимита'!$J$58,Подложка!E24:E26,0)) -> 1
C32: Коды ОКВЭД 41-43, 71 | H32: Коды ОКВЭД 06, 49.5, 09, 19.2 | M32: Коды ОКВЭД 49-53, за искл. 49.5, 51, 50 | R32: Коды ОКВЭД 45-47 | W32: Коды ОКВЭД 05, 07-08, 10-33, 35, за искл.19.2 | AB32: Коды ОКВЭД 51 | AG32: Коды ОКВЭД 50 | AL32: Остальные коды ОКВЭД | AQ32: Коды ОКВЭД 62-63
A33: № | B33: ФИНАНСОВЫЕ ПОКАЗАТЕЛИ | C33: Строительство | H33: Добыча, переработка и транспортировка газа, нефти и нефтепродуктов | M33: Транспортировка и хранение | R33: Торговля | W33: Производство | AB33: Авиакомпания | AG33: Судовладелец | AL33: Прочие | AQ33: ИТ
B34: Кол-во баллов | C34: 40 | D34: 70 | E34: 100 | H34: 40 | I34: 70 | J34: 100 | M34: 40 | N34: 70 | O34: 100 | R34: 40 | S34: 70 | T34: 100 | W34: 40 | X34: 70 | Y34: 100 | AB34: 40 | AC34: 70 | AD34: 100 | AG34: 40 | AH34: 70 | AI34: 100 | AL34: 40 | AM34: 70 | AN34: 100 | AQ34: 40 | AR34: 70 | AS34: 100
A35: 1.1 | B35: Коэффициент текущей ликвидности | C35: 1 | D35: 1.4 | E35: 2.2 | H35: 0.9 | I35: 1.3 | J35: 2.2 | M35: 0.8 | N35: 1.2 | O35: 2 | R35: 1.1 | S35: 1.5 | T35: 2.4 | W35: 1 | X35: 1.5 | Y35: 2.6 | AB35: 1 | AC35: 1.9 | AD35: 3.2 | AG35: 0.7 | AH35: 1.3 | AI35: 2.5 | AL35: 1 | AM35: 1.6 | AN35: 3.4 | AQ35: 1.1 | AR35: 1.9 | AS35: 3.4
A36: 1.2 | B36: Коэффициент быстрой ликвидности | C36: 0.7 | D36: 1.1 | E36: 1.7 | H36: 0.6 | I36: 1 | J36: 1.7 | M36: 0.6 | N36: 1.1 | O36: 1.7 | R36: 0.5 | S36: 0.9 | T36: 1.4 | W36: 0.5 | X36: 0.9 | Y36: 1.5 | AB36: 0.7 | AC36: 1.4 | AD36: 2.7 | AG36: 0.5 | AH36: 1 | AI36: 1.8 | AL36: 0.7 | AM36: 1.2 | AN36: 2.5 | AQ36: 0.8 | AR36: 1.3 | AS36: 2.7
A37: 1.3 | B37: Длительность операционного цикла | C37: 80 | D37: 30 | E37: 0 | H37: 90 | I37: 35 | J37: 0 | M37: 50 | N37: 20 | O37: 0 | R37: 60 | S37: 30 | T37: 5 | W37: 120 | X37: 50 | Y37: 2 | AB37: 95 | AC37: 30 | AD37: 0 | AG37: 70 | AH37: 20 | AI37: 0 | AL37: 70 | AM37: 20 | AN37: 0 | AQ37: 85 | AR37: 25 | AS37: 0
A38: 1.4 | B38: Коэффициент автономии | C38: 0.1 | D38: 0.4 | E38: 0.6 | H38: 0.1 | I38: 0.4 | J38: 0.7 | M38: 0.1 | N38: 0.3 | O38: 0.6 | R38: 0.1 | S38: 0.3 | T38: 0.6 | W38: 0.2 | X38: 0.4 | Y38: 0.7 | AB38: 0.1 | AC38: 0.4 | AD38: 0.8 | AG38: 0.1 | AH38: 0.3 | AI38: 0.7 | AL38: 0.2 | AM38: 0.5 | AN38: 0.8 | AQ38: 0.2 | AR38: 0.5 | AS38: 0.8
A39: 1.5 | B39: Рентабельность продаж | C39: 2 | D39: 6 | E39: 13 | H39: 1 | I39: 6 | J39: 13 | M39: 1 | N39: 5 | O39: 11 | R39: 1 | S39: 3 | T39: 6 | W39: 2 | X39: 7 | Y39: 15 | AB39: 0 | AC39: 4 | AD39: 12 | AG39: 0 | AH39: 4 | AI39: 17 | AL39: 2 | AM39: 9 | AN39: 22 | AQ39: 2 | AR39: 10 | AS39: 19
A40: 1.6 | B40: Коэффициент долговой нагрузки | C40: 1.1 | D40: 0.3 | E40: 0 | H40: 3.3 | I40: 1.3 | J40: 0 | M40: 2.5 | N40: 0.8 | O40: 0.2 | R40: 3.7 | S40: 1.5 | T40: 0.3 | W40: 2.7 | X40: 0.9 | Y40: 0.1 | AB40: 0.9 | AC40: 0.3 | AD40: 0 | AG40: 1.6 | AH40: 0.3 | AI40: 0 | AL40: 0.9 | AM40: 0.3 | AN40: 0 | AQ40: 1.5 | AR40: 0.2 | AS40: 0
A41: 1.7 | B41: Коэффициент покрытия процентов | C41: 1.2 | D41: 3.2 | E41: 11.5 | H41: 0.5 | I41: 2.2 | J41: 8.1 | M41: 1.1 | N41: 2 | O41: 4.9 | R41: 0.9 | S41: 1.6 | T41: 4.4 | W41: 1.1 | X41: 2.8 | Y41: 9.2 | AB41: 1.1 | AC41: 2.6 | AD41: 5.9 | AG41: 0 | AH41: 1.4 | AI41: 4.9 | AL41: 0.8 | AM41: 2.5 | AN41: 9.3 | AQ41: 0.5 | AR41: 3.1 | AS41: 18.2
A42: 1.8 | B42: Коэффициент маневренности | C42: -0.1 | D42: 0.2 | E42: 0.5 | H42: -0.4 | I42: 0 | J42: 0.4 | M42: -0.6 | N42: 0 | O42: 0.4 | R42: 0 | S42: 0.2 | T42: 0.5 | W42: -0.2 | X42: 0.2 | Y42: 0.6 | AB42: -0.6 | AC42: 0.1 | AD42: 0.6 | AG42: -0.7 | AH42: 0 | AI42: 0.4 | AL42: -0.2 | AM42: 0.3 | AN42: 0.7 | AQ42: 0.1 | AR42: 0.4 | AS42: 0.7
A43: 1.9 | B43: Рентабельность капитала | C43: 4 | D43: 19 | E43: 43 | H43: 1 | I43: 10 | J43: 26 | M43: 5 | N43: 15 | O43: 30 | R43: 6 | S43: 20 | T43: 43 | W43: 5 | X43: 15 | Y43: 32 | AB43: 1 | AC43: 12 | AD43: 42 | AG43: 2 | AH43: 14 | AI43: 39 | AL43: 3 | AM43: 16 | AN43: 45 | AQ43: 4 | AR43: 24 | AS43: 66
...

Sheet МСФО расчет лимита
F1: ЭКСПРЕСС-ОЦЕНКА КОНТРАГЕНТА
K3: Дата оценки | N3: (Голубая ячейка заполняется вручную)
B5: ДАННЫЕ О КОНТРАГЕНТЕ
B7: 1.1 Наименование контрагента: | H7: СНПХ, АО | N7: (Голубая ячейка заполняется вручную)
B8: 1.2 Идентификационный номер (TIN): | H8: 1660000129 | N8: (Голубая ячейка заполняется вручную)
B9: 1.3 Код контрагента в системе учета (при наличии): | N9: (Заполняется вручную)
B10: 1.3 Категория: | H10: Производство | N10: (В голубой ячейке выбрать значение из списка)
B11: 1.4 Наличие СТОП-факторов: | H11: Нет | N11: (В голубой ячейке выбрать значение из списка)
B13: ИТОГОВОЕ ЗАКЛЮЧЕНИЕ
H14: =J22 -> 46022 | L14: ='МСФО отчетность'!F5 -> 45657 | N14: (Автоматический расчет)
B15: ВНУТРЕННИЙ КРЕДИТНЫЙ РЕЙТИНГ | H15: =J58&J57 -> C1 | J15: =J57 -> 1 | M15: =L58&L57 -> B1 | N15: (Автоматический расчет)
B16: СКОРИНГ-БАЛЛ | H16: =ROUND(J55,0)&" "&K55 -> 74 из 100 | J16: =J55 -> 74 | M16: =L55&" "&K55 -> 70 из 100 | N16: (Автоматический расчет)
B17: ="КРЕДИТНЫЙ ЛИМИТ КОНТРАГЕНТА, "&'МСФО отчетность'!C2&" "&'МСФО отчетность'!C3 -> КРЕДИТНЫЙ ЛИМИТ КОНТРАГЕНТА, mln $ | H17: =J89 -> 1491319.8 | J17: =H17 -> 1491319.8 | K17: =L83*L85*L87*(1-L88) -> 1223618.2 | L17: =L89 -> 1223618.2 | N17: (Автоматический расчет)
B18: ="ЛИМИТ АВАНСОВОГО ПЛАТЕЖА, "&'МСФО отчетность'!C2&" "&'МСФО отчетность'!C3 -> ЛИМИТ АВАНСОВОГО ПЛАТЕЖА, mln $ | H18: =J90 -> 52141.5 | J18: =H18 -> 52141.5 | L18: =L90 -> 35823.9
B20: 1. ФИНАНСОВЫЕ ПОКАЗАТЕЛИ
J22: ='МСФО отчетность'!E5 -> 46022 | L22: ='МСФО отчетность'!F5 -> 45657 | N22: (Автоматический расчет)
B23: Наименование показателя | I23: Макс. балл | J23: Значение | K23: Баллы | L23: Значение | M23: Баллы
B24: 1.1 Коэффициент текущей ликвидности | I24: 10 | J24: ='МСФО отчетность'!E64 -> 3.2836953 | K24: =ROUND(IF(J24="",0,IF($H$10="Строительство",Подложка!G92*I24/100,IF($H$10="Добыча, переработка и транспортировка газа, нефти и нефтепродуктов",Подложка!L92*I24/100,IF($H$10="Транспортировка и хранение",Подложка!Q92*I24/100,IF($H$10="Торговля",Подложка!V92*I24/100,IF($H$10="Производство",Подложка!AA92*I24/100,IF($H$10="Авиакомпания",Подложка!AF92*I24/100,IF($H$10="Судовладелец",Подложка!AK92*I24/100,IF($H$10="Прочие",Подложка!AP92*I24/100,IF($H$10="ИТ",Подложка!AU92*I24/100,0)))))))))),0) -> 10 | L24: ='МСФО отчетность'!F64 -> 2.9821276 | M24: =IF(L24="",0,IF($H$10="Строительство",Подложка!G55*I24/100,IF($H$10="Добыча, переработка и транспортировка газа, нефти и нефтепродуктов",Подложка!L55*I24/100,IF($H$10="Транспортировка и хранение",Подложка!Q55*I24/100,IF($H$10="Торговля",Подложка!V55*I24/100,IF($H$10="Производство",Подложка!AA55*I24/100,IF($H$10="Авиакомпания",Подложка!AF55*I24/100,IF($H$10="Судовладелец",Подложка!AK55*I24/100,IF($H$10="Прочие",Подложка!AP55*I24/100,IF($H$10="ИТ",Подложка!AU55*I24/100,0)))))))))) -> 10 | N24: (Автоматический расчет)
B25: 1.2 Коэффициент быстрой ликвидности | I25: 5 | J25: ='МСФО отчетность'!E65 -> 1.7494151 | K25: =ROUND(IF(J25="",0,IF($H$10="Строительство",Подложка!G93*I25/100,IF($H$10="Добыча, переработка и транспортировка газа, нефти и нефтепродуктов",Подложка!L93*I25/100,IF($H$10="Транспортировка и хранение",Подложка!Q93*I25/100,IF($H$10="Торговля",Подложка!V93*I25/100,IF($H$10="Производство",Подложка!AA93*I25/100,IF($H$10="Авиакомпания",Подложка!AF93*I25/100,IF($H$10="Судовладелец",Подложка!AK93*I25/100,IF($H$10="Прочие",Подложка!AP93*I25/100,IF($H$10="ИТ",Подложка!AU93*I25/100,0)))))))))),0) -> 5 | L25: ='МСФО отчетность'!F65 -> 1.755559 | M25: =IF(L25="",0,IF($H$10="Строительство",Подложка!G56*I25/100,IF($H$10="Добыча, переработка и транспортировка газа, нефти и нефтепродуктов",Подложка!L56*I25/100,IF($H$10="Транспортировка и хранение",Подложка!Q56*I25/100,IF($H$10="Торговля",Подложка!V56*I25/100,IF($H$10="Производство",Подложка!AA56*I25/100,IF($H$10="Авиакомпания",Подложка!AF56*I25/100,IF($H$10="Судовладелец",Подложка!AK56*I25/100,IF($H$10="Прочие",Подложка!AP56*I25/100,IF($H$10="ИТ",Подложка!AU56*I25/100,0)))))))))) -> 5 | N25: (Автоматический расчет)
B26: 1.3 Длительность операционного цикла | I26: 5 | J26: ='МСФО отчетность'!E66 -> 166.83719 | K26: =ROUND(IF($H$10="Строительство",Подложка!G94*I26/100,IF($H$10="Добыча, переработка и транспортировка газа, нефти и нефтепродуктов",Подложка!L94*I26/100,IF($H$10="Транспортировка и хранение",Подложка!Q94*I26/100,IF($H$10="Торговля",Подложка!V94*I26/100,IF($H$10="Производство",Подложка!AA94*I26/100,IF($H$10="Авиакомпания",Подложка!AF94*I26/100,IF($H$10="Судовладелец",Подложка!AK94*I26/100,IF($H$10="Прочие",Подложка!AP94*I26/100,IF($H$10="ИТ",Подложка!AU94*I26/100,0))))))))),0) -> 0 | L26: ='МСФО отчетность'!F66 -> 140.56013 | M26: =IF(L26="",0,IF($H$10="Строительство",Подложка!G57*I26/100,IF($H$10="Добыча, переработка и транспортировка газа, нефти и нефтепродуктов",Подложка!L57*I26/100,IF($H$10="Транспортировка и хранение",Подложка!Q57*I26/100,IF($H$10="Торговля",Подложка!V57*I26/100,IF($H$10="Производство",Подложка!AA57*I26/100,IF($H$10="Авиакомпания",Подложка!AF57*I26/100,IF($H$10="Судовладелец",Подложка!AK57*I26/100,IF($H$10="Прочие",Подложка!AP57*I26/100,IF($H$10="ИТ",Подложка!AU57*I26/100,0)))))))))) -> 0 | N26: (Автоматический расчет)
B27: 1.4 Коэффициент автономии | I27: 10 | J27: ='МСФО отчетность'!E67 -> 0.70509515 | K27: =ROUND(IF(J27="",0,IF($H$10="Строительство",Подложка!G95*I27/100,IF($H$10="Добыча, переработка и транспортировка газа, нефти и нефтепродуктов",Подложка!L95*I27/100,IF($H$10="Транспортировка и хранение",Подложка!Q95*I27/100,IF($H$10="Торговля",Подложка!V95*I27/100,IF($H$10="Производство",Подложка!AA95*I27/100,IF($H$10="Авиакомпания",Подложка!AF95*I27/100,IF($H$10="Судовладелец",Подложка!AK95*I27/100,IF($H$10="Прочие",Подложка!AP95*I27/100,IF($H$10="ИТ",Подложка!AU95*I27/100,0)))))))))),0) -> 10 | L27: ='МСФО отчетность'!F67 -> 0.67351065 | M27: =IF(L27="",0,IF($H$10="Строительство",Подложка!G58*I27/100,IF($H$10="Добыча, переработка и транспортировка газа, нефти и нефтепродуктов",Подложка!L58*I27/100,IF($H$10="Транспортировка и хранение",Подложка!Q58*I27/100,IF($H$10="Торговля",Подложка!V58*I27/100,IF($H$10="Производство",Подложка!AA58*I27/100,IF($H$10="Авиакомпания",Подложка!AF58*I27/100,IF($H$10="Судовладелец",Подложка!AK58*I27/100,IF($H$10="Прочие",Подложка!AP58*I27/100,IF($H$10="ИТ",Подложка!AU58*I27/100,0)))))))))) -> 7 | N27: (Автоматический расчет)
B28: 1.5 Рентабельность продаж | I28: 5 | J28: ='МСФО отчетность'!E68 -> 9.6934592 | K28: =ROUND(IF(J28="",0,IF($H$10="Строительство",Подложка!G96*I28/100,IF($H$10="Добыча, переработка и транспортировка газа, нефти и нефтепродуктов",Подложка!L96*I28/100,IF($H$10="Транспортировка и хранение",Подложка!Q96*I28/100,IF($H$10="Торговля",Подложка!V96*I28/100,IF($H$10="Производство",Подложка!AA96*I28/100,IF($H$10="Авиакомпания",Подложка!AF96*I28/100,IF($H$10="Судовладелец",Подложка!AK96*I28/100,IF($H$10="Прочие",Подложка!AP96*I28/100,IF($H$10="ИТ",Подложка!AU96*I28/100,0)))))))))),0) -> 4 | L28: ='МСФО отчетность'!F68 -> 21.337774 | M28: =IF(L28="",0,IF($H$10="Строительство",Подложка!G59*I28/100,IF($H$10="Добыча, переработка и транспортировка газа, нефти и нефтепродуктов",Подложка!L59*I28/100,IF($H$10="Транспортировка и хранение",Подложка!Q59*I28/100,IF($H$10="Торговля",Подложка!V59*I28/100,IF($H$10="Производство",Подложка!AA59*I28/100,IF($H$10="Авиакомпания",Подложка!AF59*I28/100,IF($H$10="Судовладелец",Подложка!AK59*I28/100,IF($H$10="Прочие",Подложка!AP59*I28/100,IF($H$10="ИТ",Подложка!AU59*I28/100,0)))))))))) -> 5 | N28: (Автоматический расчет)
B29: 1.6 Коэффициент долговой нагрузки | I29: 10 | J29: ='МСФО отчетность'!E69 -> 0.30470929 | K29: =ROUND(IF(J29=0,I29,IF(OR(J29="",J29<0),0,IF($H$10="Строительство",Подложка!G97*I29/100,IF($H$10="Добыча, переработка и транспортировка газа, нефти и нефтепродуктов",Подложка!L97*I29/100,IF($H$10="Транспортировка и хранение",Подложка!Q97*I29/100,IF($H$10="Торговля",Подложка!V97*I29/100,IF($H$10="Производство",Подложка!AA97*I29/100,IF($H$10="Авиакомпания",Подложка!AF97*I29/100,IF($H$10="Судовладелец",Подложка!AK97*I29/100,IF($H$10="Прочие",Подложка!AP97*I29/100,IF($H$10="ИТ",Подложка!AU97*I29/100,0))))))))))),0) -> 7 | L29: ='МСФО отчетность'!F69 -> 0.16220914 | M29: =IF(L29="",0,IF($H$10="Строительство",Подложка!G60*I29/100,IF($H$10="Добыча, переработка и транспортировка газа, нефти и нефтепродуктов",Подложка!L60*I29/100,IF($H$10="Транспортировка и хранение",Подложка!Q60*I29/100,IF($H$10="Торговля",Подложка!V60*I29/100,IF($H$10="Производство",Подложка!AA60*I29/100,IF($H$10="Авиакомпания",Подложка!AF60*I29/100,IF($H$10="Судовладелец",Подложка!AK60*I29/100,IF($H$10="Прочие",Подложка!AP60*I29/100,IF($H$10="ИТ",Подложка!AU60*I29/100,0)))))))))) -> 7 | N29: (Автоматический расчет)
B30: 1.7 Коэффициент покрытия процентов | I30: 5 | J30: ='МСФО отчетность'!E70 -> 18.721681 | K30: =ROUND(IF(J30=0,I30,IF(OR(J30="",J30<0),0,IF($H$10="Строительство",Подложка!G98*I30/100,IF($H$10="Добыча, переработка и транспортировка газа, нефти и нефтепродуктов",Подложка!L98*I30/100,IF($H$10="Транспортировка и хранение",Подложка!Q98*I30/100,IF($H$10="Торговля",Подложка!V98*I30/100,IF($H$10="Производство",Подложка!AA98*I30/100,IF($H$10="Авиакомпания",Подложка!AF98*I30/100,IF($H$10="Судовладелец",Подложка!AK98*I30/100,IF($H$10="Прочие",Подложка!AP98*I30/100,IF($H$10="ИТ",Подложка!AU98*I30/100,0))))))))))),0) -> 5 | L30: ='МСФО отчетность'!F70 -> 34.086001 | M30: =IF(L30="",0,IF($H$10="Строительство",Подложка!G61*I30/100,IF($H$10="Добыча, переработка и транспортировка газа, нефти и нефтепродуктов",Подложка!L61*I30/100,IF($H$10="Транспортировка и хранение",Подложка!Q61*I30/100,IF($H$10="Торговля",Подложка!V61*I30/100,IF($H$10="Производство",Подложка!AA61*I30/100,IF($H$10="Авиакомпания",Подложка!AF61*I30/100,IF($H$10="Судовладелец",Подложка!AK61*I30/100,IF($H$10="Прочие",Подложка!AP61*I30/100,IF($H$10="ИТ",Подложка!AU61*I30/100,0)))))))))) -> 5 | N30: (Автоматический расчет)
B31: 1.8 Коэффициент маневренности | I31: 5 | J31: ='МСФО отчетность'!E71 -> 0.68527449 | K31: =ROUND(IF(J24="",0,IF(OR(J31="",J31<0),0,IF($H$10="Строительство",Подложка!G99*I31/100,IF($H$10="Добыча, переработка и транспортировка газа, нефти и нефтепродуктов",Подложка!L99*I31/100,IF($H$10="Транспортировка и хранение",Подложка!Q99*I31/100,IF($H$10="Торговля",Подложка!V99*I31/100,IF($H$10="Производство",Подложка!AA99*I31/100,IF($H$10="Авиакомпания",Подложка!AF99*I31/100,IF($H$10="Судовладелец",Подложка!AK99*I31/100,IF($H$10="Прочие",Подложка!AP99*I31/100,IF($H$10="ИТ",Подложка!AU99*I31/100,0))))))))))),0) -> 5 | L31: ='МСФО отчетность'!F71 -> 0.65401698 | M31: =IF(L31="",0,IF($H$10="Строительство",Подложка!G62*I31/100,IF($H$10="Добыча, переработка и транспортировка газа, нефти и нефтепродуктов",Подложка!L62*I31/100,IF($H$10="Транспортировка и хранение",Подложка!Q62*I31/100,IF($H$10="Торговля",Подложка!V62*I31/100,IF($H$10="Производство",Подложка!AA62*I31/100,IF($H$10="Авиакомпания",Подложка!AF62*I31/100,IF($H$10="Судовладелец",Подложка!AK62*I31/100,IF($H$10="Прочие",Подложка!AP62*I31/100,IF($H$10="ИТ",Подложка!AU62*I31/100,0)))))))))) -> 5 | N31: (Автоматический расчет)
B32: 1.9 Рентабельность капитала | I32: 4 | J32: ='МСФО отчетность'!E72 -> 26.007659 | K32: =ROUND(IF(J32="",0,IF(OR(J32="",J32<0),0,IF($H$10="Строительство",Подложка!G100*I32/100,IF($H$10="Добыча, переработка и транспортировка газа, нефти и нефтепродуктов",Подложка!L100*I32/100,IF($H$10="Транспортировка и хранение",Подложка!Q100*I32/100,IF($H$10="Торговля",Подложка!V100*I32/100,IF($H$10="Производство",Подложка!AA100*I32/100,IF($H$10="Авиакомпания",Подложка!AF100*I32/100,IF($H$10="Судовладелец",Подложка!AK100*I32/100,IF($H$10="Прочие",Подложка!AP100*I32/100,IF($H$10="ИТ",Подложка!AU100*I32/100,0))))))))))),0) -> 3 | L32: ='МСФО отчетность'!F72 -> 65.990771 | M32: =IF(L32="",0,IF($H$10="Строительство",Подложка!G63*I32/100,IF($H$10="Добыча, переработка и транспортировка газа, нефти и нефтепродуктов",Подложка!L63*I32/100,IF($H$10="Транспортировка и хранение",Подложка!Q63*I32/100,IF($H$10="Торговля",Подложка!V63*I32/100,IF($H$10="Производство",Подложка!AA63*I32/100,IF($H$10="Авиакомпания",Подложка!AF63*I32/100,IF($H$10="Судовладелец",Подложка!AK63*I32/100,IF($H$10="Прочие",Подложка!AP63*I32/100,IF($H$10="ИТ",Подложка!AU63*I32/100,0)))))))))) -> 4 | N32: (Автоматический расчет)
B33: 1.10 Динамика ликвидности | I33: 3 | J33: ='МСФО отчетность'!E73 -> Рост | K33: =VLOOKUP(J33,Подложка!$AD$3:$AE$6,2,0) -> 3 | L33: ='МСФО отчетность'!F73 -> На прежнем уровне | M33: =VLOOKUP(L33,Подложка!$AD$3:$AE$6,2,0) -> 0 | N33: (Автоматический расчет)
B34: 1.11 Динамика рентабельности продаж | I34: 3 | J34: ='МСФО отчетность'!E74 -> Снижение | K34: =VLOOKUP(J34,Подложка!$AD$3:$AE$6,2,0) -> -3 | L34: ='МСФО отчетность'!F74 -> Снижение | M34: =VLOOKUP(L34,Подложка!$AD$3:$AE$6,2,0) -> -3 | N34: (Автоматический расчет)
B35: Итого баллов с учетом веса показателей | I35: =SUM(I24:I34) -> 65 | K35: =SUM(K24:K34) -> 49 | M35: =SUM(M24:M34) -> 45 | N35: (Автоматический расчет)
B37: 2. ПОКАЗАТЕЛИ ДЕЛОВОЙ РЕПУТАЦИИ
J39: ='МСФО отчетность'!E5 -> 46022 | L39: ='МСФО отчетность'!F5 -> 45657 | N39: (Автоматический расчет)
B40: Наименование показателя | I40: Макс. балл | J40: Значение | K40: Баллы | L40: Значение | M40: Баллы
B41: 2.1 Опыт работы с контрагентом | I41: 10 | J41: более 3-х лет | K41: =IF($J$41="более 3-х лет",100*I41/100,IF($J$41="от 1 до 3-х лет",70*I41/100,IF($J$41="менее 1 года",40*I41/100,0))) -> 10 | L41: более 3-х лет | M41: =IF($L$41="более 3-х лет",100*I41/100,IF($L$41="от 1 до 3-х лет",70*I41/100,IF($L$41="менее 1 года",40*I41/100,0))) -> 10 | N41: (В голубых ячейках выбрать значение из списка)
B42: 2.2 Платежная дисциплина контрагента | I42: 15 | J42: ПДЗ отсутствовала | K42: =IF(OR(J42="ПДЗ отсутствовала",J42="Техническая ПДЗ"),15,IF(J42="Разовая ПДЗ продолжительностью менее 30 дней",10,IF(J42="Разовая ПДЗ продолжительностью более 30 дней",7.5,IF(J42="Неоднократное возникновение ПДЗ",3.5,IF(J42="Информация отсутствует",3.5,0))))) -> 15 | L42: ПДЗ отсутствовала | M42: =IF(OR(L42="ПДЗ отсутствовала",L42="Техническая ПДЗ"),15,IF(L42="Разовая ПДЗ продолжительностью менее 30 дней",10,IF(L42="Разовая ПДЗ продолжительностью более 30 дней",7.5,IF(L42="Неоднократное возникновение ПДЗ",3.5,IF(L42="Информация отсутствует",3.5,0))))) -> 15 | N42: (В голубых ячейках выбрать значение из списка)
B43: Итого баллов с учетом веса показателей | I43: 25 | K43: =SUM(K41:K42) -> 25 | M43: =SUM(M41:M42) -> 25 | N43: (Автоматический расчет)
B45: 3. ПОКАЗАТЕЛИ ИЗ ВНЕШНИХ ИСТОЧНИКОВ
J48: ='МСФО отчетность'!E5 -> 46022 | N48: (Автоматический расчет)
B49: Повышающие показатели | I49: Макс. балл | J49: Значение | K49: Баллы | L49: Дата регистрации
B50: 3.1 Возраст компании | I50: 10 | J50: =IF(OR(L98="",L98=0),"Информация отсутствует",IF(L98>TODAY(),"Информация некорректна",IF(TODAY()-L98<730,"Менее 2 лет",IF(TODAY()-L98<1825,"От 2 до 5-и лет","Более 5 лет")))) -> Информация отсутствует | K50: =IF(OR(L98="Информация отсутствует",L98="Информация некорректна"),0,IF(L98="Менее 2 лет",40*I98/100,IF(L98="От 2 до 5-и лет",70*I98/100,100*I98/100))) -> 0 | L50: 34928 | N50: (Голубая ячейка заполняется вручную)
B51: Итого баллов с учетом веса показателей | I51: 10 | K51: =IF(ROUND(SUM(K98),2)<0,0,ROUND(SUM(K98),2)) -> 0 | N51: (Автоматический расчет)
...

Sheet МСФО отчетность
A1: ДАННЫЕ ОТЧЕТНОСТИ | G1: заполнять вручную
A2: Unit | C2: mln | G2: заполняется автоматически
A3: Currency | C3: $
A4: Statement of Financial Position
E5: 46022 | F5: 45657 | G5: 45291
A6: ASSETS
A7: I. Non-current assets: | E7: =SUM(E8:E14) -> 199517 | F7: =SUM(F8:F14) -> 158892 | G7: =SUM(G8:G14) -> 136886
A8: Property, plant and equipment | E8: 173805 | F8: 119413 | G8: 94029
A9: Goodwill and other intangible assets
A10: Investments in associates and joint ventures
A11: Long-term trade and other receivables
A12: Long-term financial assets | E12: 900 | F12: 812 | G12: 822
A13: Deferred tax assets | E13: 6642 | F13: 5504 | G13: 2382
A14: Other non-current assets | E14: =18170 -> 18170 | F14: 33163 | G14: 39653
A15: II. Current assets: | E15: =SUM(E16:E18,E20:E22) -> 2935952 | F15: =SUM(F16:F18,F20:F22) -> 2661200 | G15: =SUM(G16:G18,G20:G22) -> 1806482
A16: Cash and cash equivalents | E16: 210093 | F16: 96119 | G16: 44876
A17: Short-term financial assets | E17: 0 | F17: 15000 | G17: 75905
A18: Trade and other receivables | E18: 1354059 | F18: 1470512 | G18: 732868
A19: Receivables from stakeholders
A20: Inventories | E20: 1351289 | F20: 1061615 | G20: 932045
A21: Current tax prepayments | E21: 7 | F21: 0 | G21: 0
A22: Other current assets | E22: 20504 | F22: 17954 | G22: 20788
A23: TOTAL ASSETS | E23: =E7+E15 -> 3135469 | F23: =F7+F15 -> 2820092 | G23: =G7+G15 -> 1943368
A24: LIABILITIES AND SHAREHOLDER'S EQUITY
A25: III. Equity | E25: =SUM(E26:E32) -> 2210804 | F25: =SUM(F26:F32) -> 1899362 | G25: =SUM(G26:G32) -> 1345353
A26: Share capital | E26: 19896 | F26: 19896 | G26: 19896
A27: Equity attributable to owners of the Company
A28: Reserves | E28: 20729 | F28: 86449 | G28: 86449
A29: Other reserves | E29: 995 | F29: 995 | G29: 995
A30: Additional paid-in capital | E30: 33333 | F30: 33333 | G30: 33333
A31: Retained earnings | E31: 2135851 | F31: 1758689 | G31: 1204680
A32: Non-controlling interests
A33: IV. Long-term liabilities | E33: =SUM(E34:E39) -> 4010 | F33: =SUM(F34:F39) -> 7556 | G33: =SUM(G34:G39) -> 7277
A34: Loans and borrowings
A35: Other non-current financial liabilities
A36: Deferred tax liabilities | E36: 4010 | F36: 7556 | G36: 7277
A37: Provisions
A38: Trade and other payables
A39: Other non-current liabilities
A40: V. Short-term liabilities | E40: =SUM(E41:E47) -> 920655 | F40: =SUM(F41:F47) -> 913174 | G40: =SUM(G41:G47) -> 590738
...
